<?xml version="1.0"?>
<robot xmlns:xacro="http://www.ros.org/wiki/xacro" >



  <!-- In order to move the youbot without use wheels>
  <link name="world" />
  <link name="virtual_link_xy" />

  <joint name="virtual_joint_x" type="prismatic">
    <axis xyz="1 0 0"/>
    <parent link="world" />
    <child link="virtual_link_xy" />
    <limit effort="1" lower="-5" upper="5" velocity="1"/>
  </joint>

  <link name="virtual_link_yz" />

  <joint name="virtual_joint_y" type="prismatic">
    <axis xyz="0 1 0"/>
    <parent link="virtual_link_xy" />
    <child link="virtual_link_yz" />
    <limit effort="1" lower="-5" upper="5" velocity="1"/>
  </joint>

  <joint name="virtual_joint_z" type="continuous">
    <axis xyz="0 0 1"/>
    <origin xyz="0 0 0.1"/> 
    <parent link="virtual_link_yz" />
    <child link="base_link" />
  </joint>

  <<gazebo>
    <plugin filename="libgazebo_ros2_control.so" name="gazebo_ros2_control">
      <parameters>config/youbot.yaml</parameters>
    </plugin>
  </gazebo>-->




  <link name="base_link">

  </link>




  <joint name="base_footprint_joint" type="fixed">
    <origin rpy="0 0 0" xyz="0 0 0"/>
    <parent link="base_link"/>
    <child link="base_footprint"/>
  </joint>

  <link name="base_footprint">
  </link>

  

    <!--inertial>
      <mass value="0.0001"/>
      <origin rpy="0 0 0" xyz="0 0 -0.05"/>
      <inertia ixx="1.0" ixy="0.0" ixz="0.0" iyy="1.0" iyz="0.0" izz="1.0"/>
    </inertial-->
    <!--visual>
      <origin rpy="0 0 0" xyz="0 0 0"/>
      <geometry>
        <box size="0.001 0.001 0.001"/>
      </geometry>
    </visual>
    <collision>
      <origin rpy="0 0 0" xyz="0 0 0"/>
      <geometry>
        <box size="0.001 0.001 0.001"/>
      </geometry>
    </collision>
  
  <joint name="base_link_joint" type="fixed">
    <origin rpy="0 0 0" xyz="0 0 0.084"/>
    <child link="chassis"/>
    <parent link="base_link"/>
  </joint-->




<!--###################chassis_joint#########################-->

<joint name="chassis_joint" type="fixed">
 <origin rpy="0 0 0" xyz="0 0 0.084"/>
    <parent link="base_link"/>
    <child link="chassis"/>
    <origin xyz="0 0 0"/>
</joint>

  <link name="chassis">
    <inertial>
      <mass value="2.0"/>
      <origin xyz="0 0 0"/>
      <inertia
        ixx="0.774276574699151"
        ixy="-1.03781944357671E-10"
        ixz="0.00763014265820928"
        iyy="1.64933255189991"
        iyz="1.09578155845563E-12"
        izz="2.1239326987473" />
      <!--inertia ixx="6.652232699207" ixy="-0.009719934438" ixz="1.293988226423" iyy="6.669473158652" iyz="-0.007379583694" izz="4.683196351726"/-->
    </inertial>
    <visual>
      <origin rpy="0 0 0" xyz="0 0 0"/>
      <geometry>
        <mesh filename="file://$(find mark3)/meshes/youbot_base/base.dae"/>
      </geometry>
    </visual>
    <collision>
      <origin rpy="0 0 0" xyz="0 0 0"/>
      <geometry>
        <mesh filename="file://$(find mark3)/meshes/youbot_base/base_convex.dae"/>
      </geometry>
    </collision>
  </link>

<!--move-->
<joint name="left_wheel_joint" type="continuous">
<axis xyz="0 0 1"/>
<origin rpy="-${pi/2} 0 0" xyz="0.0 0.158 -0.034"/>
<parent link="chassis"/>
<child link="left_wheel"/>
</joint>

<link name="left_wheel">
    <visual>
        <geometry>
            <cylinder length="0.0001" radius="0.05"/>
        </geometry>
    </visual>
    <collision>
        <geometry>
            <sphere radius="0.051"/>
        </geometry>
    </collision>
    <inertial>
      <origin
        xyz="-4.1867E-18 0.0068085 -1.65658661799998E-18"
        rpy="0 0 0" />
      <mass
        value="0.0578" />
      <inertia
        ixx="0.00856502765719703"
        ixy="1.5074118157338E-19"
        ixz="-4.78150098725052E-19"
        iyy="0.013670640432096"
        iyz="-2.68136447099727E-19"
        izz="0.00856502765719703" />
    </inertial>
</link>

<joint name="right_wheel_joint" type="continuous">
<parent link="chassis"/>
<child link="right_wheel"/>
<axis xyz="0 0 -1"/>
<origin rpy="${pi/2} 0 0" xyz="0.0 -0.158 -0.034"/>
</joint>

<link name="right_wheel">
    <visual>
        <geometry>
            <cylinder length="0.0001" radius="0.05"/>
        </geometry>
    </visual>
     <collision>
        <geometry>
            <sphere radius="0.051"/>
        </geometry>
    </collision>
    <inertial>
      <origin
        xyz="-4.1867E-18 0.0068085 -1.65658661799998E-18"
        rpy="0 0 0" />
      <mass
        value="0.0578" />
      <inertia
        ixx="0.00856502765719703"
        ixy="1.5074118157338E-19"
        ixz="-4.78150098725052E-19"
        iyy="0.013670640432096"
        iyz="-2.68136447099727E-19"
        izz="0.00856502765719703" />
    </inertial>
</link>
<gazebo reference="left_wheel">
    <material>Gazebo/Grey</material>
</gazebo>
<gazebo reference="right_wheel">
    <material>Gazebo/Grey</material>
</gazebo>
<!--move-->


  <joint name="caster_joint_fl" type="fixed">
    <origin rpy="0 0 0" xyz="0.228 0.158 -0.034"/>
    <axis xyz="0 0 1"/>
    <parent link="chassis"/>
    <child link="caster_link_fl"/>
  </joint>
  <link name="caster_link_fl">
    <inertial>
      <mass value="0.01"/>
      <origin xyz="0 0 0"/>
      <inertia ixx="0.012411765597" ixy="-0.000711733678" ixz="0.00050272983" iyy="0.015218160428" iyz="-0.000004273467" izz="0.011763977943"/>
    </inertial>
    <visual>
      <origin rpy="0 0 0" xyz="0 0 0"/>
      <geometry>
        <mesh filename="file://$(find mark3)/meshes/youbot_base/front-left_wheel.dae"/>
      </geometry>
    </visual>
  </link>


<!--###################wheel_joint_fl#########################-->

  <joint name="caster_joint_fr" type="fixed">
    <origin rpy="0 0 0" xyz="0.228 -0.158 -0.034"/>
    <axis xyz="0 0 1"/>
    <parent link="chassis"/>
    <child link="caster_link_fr"/>
  </joint>
  <link name="caster_link_fr">
    <inertial>
      <mass value="0.01"/>
      <origin xyz="0 0 0"/>
      <inertia ixx="0.012411765597" ixy="-0.000711733678" ixz="0.00050272983" iyy="0.015218160428" iyz="-0.000004273467" izz="0.011763977943"/>
    </inertial>
    <visual>
      <origin rpy="0 0 0" xyz="0 0 0"/>
      <geometry>
        <mesh filename="file://$(find mark3)/meshes/youbot_base/front-right_wheel.dae"/>
      </geometry>
    </visual>
  </link>


<!--###################wheel_joint_fr#########################-->

  <joint name="caster_joint_bl" type="fixed">
    <origin rpy="0 0 0" xyz="-0.228 0.158 -0.034"/>
    <axis xyz="0 0 1"/>
    <parent link="chassis"/>
    <child link="caster_link_bl"/>
  </joint>
  <link name="caster_link_bl">
    <inertial>
      <mass value="0.01"/>
      <origin xyz="0 0 0"/>
      <inertia ixx="0.012411765597" ixy="-0.000711733678" ixz="0.00050272983" iyy="0.015218160428" iyz="-0.000004273467" izz="0.011763977943"/>
    </inertial>
    <visual>
      <origin rpy="0 0 0" xyz="0 0 0"/>
      <geometry>
        <mesh filename="file://$(find mark3)/meshes/youbot_base/back-left_wheel.dae"/>
      </geometry>
    </visual>
  </link>




<!--###################wheel_joint_bl#########################-->


  <joint name="caster_joint_br" type="fixed">
    <origin rpy="0 0 0" xyz="-0.228 -0.158 -0.034"/>
    <axis xyz="0 0 1"/>
    <parent link="chassis"/>
    <child link="caster_link_br"/>
  </joint>
  <link name="caster_link_br">
    <inertial>
      <mass value="0.01"/>
      <origin xyz="0 0 0"/>
      <inertia ixx="0.012411765597" ixy="-0.000711733678" ixz="0.00050272983" iyy="0.015218160428" iyz="-0.000004273467" izz="0.011763977943"/>
    </inertial>
    <visual>
      <origin rpy="0 0 0" xyz="0 0 0"/>
      <geometry>
        <mesh filename="file://$(find mark3)/meshes/youbot_base/back-right_wheel.dae"/>
      </geometry>
    </visual>
  </link>



<!--###################wheel_joint_br#########################-->



<!-- CASTER WHEEL -->
<joint name="front_caster_joint" type="fixed">
    <parent link="chassis"/>
    <child link="front_caster_wheel"/>
    <origin xyz="0.228 0 -0.034" rpy="0 0 0"/>
</joint>

<link name="front_caster_wheel">
    <visual>
        <geometry>
            <sphere radius="0.05" />
        </geometry>
        <material name="grey"/>
    </visual>
    <collision>
        <geometry>
            <sphere radius="0.05" />
        </geometry>
    </collision>
    <inertial>
     <origin xyz="0 0 0" rpy="0 0 0"/>
     <mass value="0.01"/>
            <inertia ixx="${(2/5) * 0.03 * (0.05*0.05)}" ixy="0.0" ixz="0.0"
                    iyy="${(2/5) * 0.03 * (0.05*0.05)}" iyz="0.0"
                    izz="${(2/5) * 0.03 * (0.05*0.05)}" />
    </inertial>
</link>

<gazebo reference="front_caster_wheel">
    <material>Gazebo/Grey</material>
    <kp value="50000000"/>
    <mu1 value="0"/> <!-- 摩擦力設定 --> 
    <mu2 value="0"/>
</gazebo>


<joint name="back_caster_joint" type="fixed">
    <parent link="chassis"/>
    <child link="back_caster_wheel"/>
    <origin xyz="-0.228 0 -0.034" rpy="0 0 0"/>
</joint>

<link name="back_caster_wheel">
    <visual>
        <geometry>
            <sphere radius="0.05" />
        </geometry>
        <material name="grey"/>
    </visual>
    <collision>
        <geometry>
            <sphere radius="0.05" />
        </geometry>
    </collision>
    <inertial>
     <origin xyz="0 0 0" rpy="0 0 0"/>
     <mass value="0.01"/>
            <inertia ixx="${(2/5) * 0.3 * (0.05*0.05)}" ixy="0.0" ixz="0.0"
                    iyy="${(2/5) * 0.3 * (0.05*0.05)}" iyz="0.0"
                    izz="${(2/5) * 0.3 * (0.05*0.05)}" />
    </inertial>
</link>

<gazebo reference="back_caster_wheel">
    <material>Gazebo/Grey</material>
    <kp value="50000000"/>
    <mu1 value="0"/> <!-- 摩擦力設定 --> 
    <mu2 value="0"/>
</gazebo>
<!-- CASTER WHEEL -->






<!--gazebo wheels friction -->
<gazebo reference="left_wheel_joint">
 <kp value="50000000"/>
 <kd value="1"/>
 <mu1 value="1"/>
 <mu2 value="1"/>
</gazebo>

<gazebo reference="right_wheel_joint">
 <kp value="50000000"/>
 <kd value="1"/>
 <mu1 value="1"/>
 <mu2 value="1"/>
</gazebo>

<gazebo reference="chassis">
 <mu1 value="0"/>
 <mu2 value="0"/>
</gazebo>

<!--gazebo wheels friction -->





  <joint name="laser_joint" type="fixed">
    <origin rpy="0 0 0" xyz="0.3 0 -0.03"/>
    <parent link="chassis"/>
    <child link="laser_frame"/>
  </joint>

  <link name="laser_frame" >
    <inertial>
      <mass value="0.001"/>
      <origin rpy="0 0 0" xyz="0 0 0"/>
      <inertia ixx="0.1" ixy="0" ixz="0" iyy="0.1" iyz="0" izz="0.1"/>
    </inertial>
    <visual>
      <origin rpy="0 0 0" xyz="0 0 0"/>
      <geometry>
        <mesh filename="file://$(find mark3)/meshes/sensors/hokuyo.dae"/>
      </geometry>
      <material name="black"/>
    </visual>
    <collision>
      <origin rpy="0 0 0" xyz="0 0 0"/>
      <geometry>
        <mesh filename="file://$(find mark3)/meshes/sensors/hokuyo_convex.dae"/>
      </geometry>
    </collision>
  </link>

<gazebo reference="laser_frame">
  <sensor name="laser" type='ray'>
    <pose frame=''>0.3 0 -0.03 0 -0 0</pose>
				<update_rate>10</update_rate>
				<visualize>true</visualize>
				<ray>
					<scan>
						<horizontal>
							<samples>360</samples>
							<min_angle>-1.57</min_angle>
							<max_angle>1.57</max_angle>
						</horizontal>
					</scan>
					<range>
						<min>0.3</min>
						<max>5.6</max>
					</range>
				</ray>
				<plugin name='laser_controller' filename='libgazebo_ros_ray_sensor.so'>
					<ros>
						<argument>-ros-args --remap ~/out:=scan</argument>
					</ros>
					<output_type>sensor_msgs/LaserScan</output_type>
          <frame_name>laser_frame</frame_name>
				</plugin>
	</sensor>
</gazebo>
  
  <transmission name="wheel_trans_r">
    <type>transmission_interface/SimpleTransmission</type>
    <joint name="right_wheel_joint"/>
    <actuator name="wheel_motor_l">
      <hardwareInterface>EffortJointInterface</hardwareInterface>
      <mechanicalReduction>79.2380952381</mechanicalReduction>
    </actuator>
  </transmission> 
  <transmission name="wheel_trans_l">
    <type>transmission_interface/SimpleTransmission</type>
    <joint name="left_joint_fl"/>
    <actuator name="wheel_motor_l">
      <hardwareInterface>EffortJointInterface</hardwareInterface>
      <mechanicalReduction>79.2380952381</mechanicalReduction>
    </actuator>
  </transmission>


  <!--transmission name="wheel_trans_fl">
    <type>transmission_interface/SimpleTransmission</type>
    <joint name="wheel_joint_fl"/>
    <actuator name="wheel_motor_fl">
      <hardwareInterface>EffortJointInterface</hardwareInterface>
      <mechanicalReduction>79.2380952381</mechanicalReduction>
    </actuator>
  </transmission>
  <transmission name="wheel_trans_fr">
    <type>transmission_interface/SimpleTransmission</type>
    <joint name="wheel_joint_fr"/>
    <actuator name="wheel_motor_fr">
      <hardwareInterface>EffortJointInterface</hardwareInterface>
      <mechanicalReduction>79.2380952381</mechanicalReduction>
    </actuator>
  </transmission>
  <transmission name="wheel_trans_bl">
    <type>transmission_interface/SimpleTransmission</type>
    <joint name="wheel_joint_bl"/>
    <actuator name="wheel_motor_bl">
      <hardwareInterface>EffortJointInterface</hardwareInterface>
      <mechanicalReduction>79.2380952381</mechanicalReduction>
    </actuator>
  </transmission>
  <transmission name="wheel_trans_br">
    <type>transmission_interface/SimpleTransmission</type>
    <joint name="wheel_joint_br"/>
    <actuator name="wheel_motor_br">
      <hardwareInterface>EffortJointInterface</hardwareInterface>
      <mechanicalReduction>79.2380952381</mechanicalReduction>
    </actuator>
  </transmission-->




  <joint name="plate_joint" type="fixed">
    <origin rpy="0 0 0" xyz="-0.159 0 0.055"/>
    <parent link="chassis"/>
    <child link="plate_link"/>
  </joint>
  <link name="plate_link">
     <inertial>
      <mass value="6"/>
      <origin rpy="0 0 0" xyz="0.01489 0.00213 0.00213"/>
      <inertia ixx="0.003863" ixy="-0.000979" ixz="0.000000" iyy="0.006196" iyz="0.000000" izz="0.006369"/>
    </inertial>
    <visual>
      <origin rpy="0 0 0" xyz="0 0 -0.025"/>
      <geometry>
        <mesh filename="file://$(find mark3)/meshes/youbot_plate/plate.dae"/>
      </geometry>
    </visual>
    <collision>
      <origin rpy="0 0 0" xyz="0 0 -0.025"/>
      <geometry>
        <mesh filename="file://$(find mark3)/meshes/youbot_plate/plate_convex.dae"/>
      </geometry>
    </collision>
  </link>


<!--#############################ARM##########################################-->

  <joint name="arm_joint_0" type="fixed">
    <origin rpy="0 0 0" xyz="0.143 0 0.046"/>
    <parent link="chassis"/>
    <child link="arm_link_0"/>
  </joint>


  <link name="arm_link_0">
    <inertial>
      <!--<origin xyz="0.023 0 0.006" rpy="0 0 0"/>-->
      <origin rpy="0 0 0" xyz="0 0 0"/>
      <mass value="0.08"/>
      <inertia ixx="0.01" ixy="0" ixz="0" iyy="0.01" iyz="0" izz="0.01"/>
    </inertial>
    <visual>
      <origin rpy="0 0 0" xyz="0 0 0"/>
      <geometry>
        <mesh filename="file://$(find mark3)/meshes/youbot_arm/arm0.dae"/>
      </geometry>
    </visual>
    <collision>
      <!--<origin xyz="0.023 0 0.006" rpy="0 0 0"/>-->
      <origin rpy="0 0 0" xyz="0 0 0"/>
      <geometry>
        <mesh filename="file://$(find mark3)/meshes/youbot_arm/arm0_convex.dae"/>
        <!--<cylinder length="0.078" radius="0.093"/>-->
      </geometry>
    </collision>
  </link>



  <joint name="arm_joint_1" type="revolute">
    <origin rpy="0 0 2.96705722222" xyz="0.024 0 0.095"/>
    <parent link="arm_link_0"/>
    <child link="arm_link_1"/>
    <axis xyz="0 0 -1"/>
    <!--<calibration rising="${arm_1_ref}" falling="${arm_1_ref}"/>-->
    <dynamics damping="1" friction="1"/>
    <!-- damping - N*s/m, N*s*m/rad -->
    <!-- friction - N, N*m -->
    <limit effort="10000.0" lower="0" upper="5.89920788889" velocity="1.570795"/>
    <!--effort - N, N*m-->
    <!--velocity - m/s, rad/s-->
    <!--k_position N/m, N/rad-->
    <!--k_velocity N*s/m, N*s*m/rad-->
    <!--for details: http://www.ros.org/wiki/pr2_controller_manager/safety_limits-->
  </joint>



  <link name="arm_link_1">
    <inertial>
      <mass value="0.02412"/>
      <origin rpy="0 0 0" xyz="0.01489 0.00213 0.00213"/>
      <inertia ixx="0.003863" ixy="-0.000979" ixz="0.000000" iyy="0.006196" iyz="0.000000" izz="0.006369"/>
    </inertial>
    <visual>
      <origin xyz="0 0 0" rpy="0 0 0" />
      <geometry>
        <mesh filename="file://$(find mark3)/meshes/youbot_arm/arm1.dae"/>
      </geometry>
    </visual>
    <collision>
      <!--<origin xyz="0 0 -0.003" rpy="0 0 0" />-->
      <origin xyz="0 0 0.02" rpy="3.14159 0 0" />
      <geometry>
        <mesh filename="file://$(find mark3)/meshes/youbot_arm/arm_joint_1_convex.stl"/>
        <!--<cylinder length="0.102" radius="0.080"/>-->
      </geometry>
    </collision>
  </link>



  <joint name="arm_joint_2" type="revolute">
    <origin rpy="0 -1.13446305556 0" xyz="0.033 0 0.02"/>
    <parent link="arm_link_1"/>
    <child link="arm_link_2"/>
    <axis xyz="0 1 0"/>
    <!--<calibration rising="${arm_2_ref}" falling="${arm_2_ref}"/>-->
    <dynamics damping="1" friction="1"/>
    <limit effort="10000.0" lower="0" upper="2.70525805556" velocity="1.570795"/>
  </joint>
  <link name="arm_link_2">
    <inertial>
      <mass value="0.00155"/>
      <origin rpy="0 0 0" xyz="0.10453 0.0017 -0.00297"/>
      <inertia ixx="0.000823" ixy="0.000000" ixz="-0.000000" iyy="0.004447" iyz="0.000000" izz="0.004439"/>
    </inertial>
    <visual>
      <origin xyz="0.001 -0.03 0.077" rpy="0 0 0" />
      <geometry>
        <mesh filename="file://$(find mark3)/meshes/youbot_arm/arm2.dae"/>
      </geometry>
    </visual>
    <collision>
      <!--<origin xyz="0.001 -0.041 0.074" rpy="0 0 0" />-->
      <origin rpy="-1.570795 -1.570795 0" xyz="0 0 0"/>
      <geometry>
        <mesh filename="file://$(find mark3)/meshes/youbot_arm/arm_joint_2_convex.stl"/>
        <!--<box size="0.074 0.082 0.222"/>-->
      </geometry>
    </collision>
  </link>



  <joint name="arm_joint_3" type="revolute">
    <origin rpy="0 2.54817855556 0" xyz="0.000 0.000 0.155"/>
    <parent link="arm_link_2"/>
    <child link="arm_link_3"/>
    <axis xyz="0 1 0"/>
    <dynamics damping="1" friction="1"/>
    <limit effort="10000.0" lower="-5.1836235" upper="0" velocity="1.570795"/>
  </joint>
  <link name="arm_link_3">
    <inertial>
      <mass value="0.00934"/>
      <origin rpy="0 0 0" xyz="0.0001 0.0967 0.02107"/>
      <inertia ixx="0.002459" ixy="0.000000" ixz="0.000000" iyy="0.002571" iyz="-0.000000" izz="0.000535"/>
    </inertial>
    <visual>
      <origin rpy="0 0 0" xyz="0.000 0.027 0.08"/>
      <geometry>
        <mesh filename="file://$(find mark3)/meshes/youbot_arm/arm3.dae"/>
      </geometry>
    </visual>
    <collision>
      <!--<origin xyz="0.000 0.025 0.067" rpy="0 0 0" />-->
      <origin rpy="1.570795 0 3.14159" xyz="0 0 0"/>
      <geometry>
        <mesh filename="file://$(find mark3)/meshes/youbot_arm/arm_joint_3_convex.stl"/>
        <!--<box size="0.064 0.054 0.192"/>-->
      </geometry>
    </collision>
  </link>



  <joint name="arm_joint_4" type="revolute">
    <origin rpy="0 -1.78896097222 0" xyz="0.000 0.000 0.135"/>
    <parent link="arm_link_3"/>
    <child link="arm_link_4"/>
    <axis xyz="0 1 0"/>
    <!--<calibration rising="${arm_4_ref}" falling="${arm_4_ref}"/>-->
    <dynamics damping="1" friction="1"/>
    <limit effort="10000.0" lower="0" upper="3.57792194444" velocity="1.570795"/>
  </joint>
  <link name="arm_link_4">
    <inertial>
      <mass value="0.000877"/>
      <origin rpy="0 0 0" xyz="0.00011 0.05103 -0.02319"/>
      <inertia ixx="0.000869" ixy="0.000000" ixz="-0.000000" iyy="0.001173" iyz="-0.000231" izz="0.001091"/>
    </inertial>
    <visual>
      <origin rpy="0 0 0" xyz="0 -0.008 0.026"/>
      <geometry>
        <mesh filename="file://$(find mark3)/meshes/youbot_arm/arm4.dae"/>
      </geometry>
    </visual>
    <collision>
      <!--<origin xyz="0 0 0.026" rpy="0 0 0" />-->
      <origin rpy="1.570795 0 3.14159" xyz="0 0 0"/>
      <geometry>
        <mesh filename="file://$(find mark3)/meshes/youbot_arm/arm_joint_4_convex.stl"/>
        <!--<box size="0.058 0.100 0.118"/>-->
      </geometry>
    </collision>
  </link>
  <joint name="arm_joint_5" type="revolute">
    <origin rpy="0 0 2.92342402778" xyz="0 0 0.114"/>
    <parent link="arm_link_4"/>
    <child link="arm_link_5"/>
    <axis xyz="0 0 -1"/>
    <!--<calibration rising="${arm_5_ref}" falling="${arm_5_ref}"/>-->
    <dynamics damping="1" friction="1"/>
    <limit effort="10000.0" lower="0" upper="5.84684805556" velocity="1.570795"/>
  </joint>
  <link name="arm_link_5">
    <inertial>
      <mass value="0.000251"/>
      <origin rpy="0 0 0" xyz="0.0 0.00115 -0.01683"/>
      <inertia ixx="0.000280" ixy="0.000000" ixz="0.000000" iyy="0.000339" iyz="0.000000" izz="0.000119"/>
    </inertial>
    <visual>
      <origin rpy="0 0 0" xyz="0 0 -0.019"/>
      <geometry>
        <mesh filename="file://$(find mark3)/meshes/youbot_arm/arm5.dae"/>
      </geometry>
    </visual>
    <collision>
      <origin rpy="0 0 0" xyz="0 0 0"/>
      <geometry>
        <mesh filename="file://$(find mark3)/meshes/youbot_arm/arm_joint_5_convex.stl"/>
        <!--<box size="0.054 0.096 0.030"/>-->
      </geometry>
    </collision>
  </link>

  <link name="pen">
    <inertial>
      <mass value="0.00001"/>
      <origin rpy="0 0 0.1" xyz="0.0 0.00115 -0.01683"/>
      <inertia ixx="0.01" ixy="0.000000" ixz="0.000000" iyy="0.01" iyz="0.000000" izz="0.01"/>
    </inertial>
    <visual>
      <origin rpy="0 0 0.05" xyz="0 0 0"/>
      <geometry>
        <cylinder length="0.1" radius="0.01"/>
      </geometry>
    </visual>
    <collision>
      <origin rpy="0 0 0.05" xyz="0 0 0"/>
      <geometry>
        <cylinder length="0.1" radius="0.01"/>
      </geometry>
    </collision>
  </link>

  <joint name="pen_joint" type="fixed">
    <origin rpy="0 0 0" xyz="0 0 0"/>
    <parent link="arm_link_5"/>
    <child link="pen"/>
    <axis xyz="0 0 -1"/>
    <dynamics damping="1" friction="1"/>
    <limit effort="10000.0" lower="0" upper="5.84684805556" velocity="1.570795"/>
  </joint>


  


  <gazebo reference="arm_link_1">
    <gravity>true</gravity>
    <selfCollide>true</selfCollide>
  </gazebo>
  <gazebo reference="arm_link_2">
    <gravity>true</gravity>
    <selfCollide>true</selfCollide>
  </gazebo>
  <gazebo reference="arm_link_3">
    <gravity>true</gravity>
    <selfCollide>true</selfCollide>
  </gazebo>
  <gazebo reference="arm_link_4">
    <gravity>true</gravity>
    <selfCollide>true</selfCollide>
  </gazebo>
  <gazebo reference="arm_link_5">
    <gravity>true</gravity>
    <selfCollide>true</selfCollide>
  </gazebo>






  <transmission name="arm_trans_1">
    <type>transmission_interface/SimpleTransmission</type>
    <joint name="arm_joint_1"/>
    <actuator name="arm_motor_1">
      <hardwareInterface>EffortJointInterface</hardwareInterface>
      <mechanicalReduction>1</mechanicalReduction>
    </actuator>
  </transmission>
  <transmission name="arm_trans_2">
    <type>transmission_interface/SimpleTransmission</type>
    <joint name="arm_joint_2"/>
    <actuator name="arm_motor_2">
      <hardwareInterface>EffortJointInterface</hardwareInterface>
      <mechanicalReduction>1</mechanicalReduction>
    </actuator>
  </transmission>
  <transmission name="arm_trans_3">
    <type>transmission_interface/SimpleTransmission</type>
    <joint name="arm_joint_3"/>
    <actuator name="arm_motor_3">
      <hardwareInterface>EffortJointInterface</hardwareInterface>
      <mechanicalReduction>1</mechanicalReduction>
    </actuator>
  </transmission>
  <transmission name="arm_trans_4">
    <type>transmission_interface/SimpleTransmission</type>
    <joint name="arm_joint_4"/>
    <actuator name="arm_motor_4">
      <hardwareInterface>EffortJointInterface</hardwareInterface>
      <mechanicalReduction>1</mechanicalReduction>
    </actuator>
  </transmission>
  <transmission name="arm_trans_5">
    <type>transmission_interface/SimpleTransmission</type>
    <joint name="arm_joint_5"/>
    <actuator name="arm_motor_5">
      <hardwareInterface>EffortJointInterface</hardwareInterface>
      <mechanicalReduction>1</mechanicalReduction>
    </actuator>
  </transmission>

  <plugin name="gazebo_ros_p3d" filename="libgazebo_ros_p3d.so">
		<ros>
			<!-- Add namespace and remap the default topic -->
			<namespace>/mark3</namespace>
			<argument>odom:=p3d</argument>
		</ros>
		<!-- Replace camelCase elements with camel_case ones -->
		<body_name>pen</body_name>
		<frame_name>ground_plane</frame_name>
		<update_rate>1</update_rate>
		<!-- <xyz_offset>1 1 1</xyz_offset>
		<rpy_offset>0.1 0.1 0.1</rpy_offset> -->
		<gaussian_noise>0.01</gaussian_noise>
  </plugin>





</robot>
